[2025-09-16T10:50:50.371+0000] {taskinstance.py:1956} INFO - Dependencies all met for dep_context=non-requeueable deps ti=<TaskInstance: dag1_test_production_summary.create_test_production_summary scheduled__2025-09-15T00:00:00+00:00 [queued]>
[2025-09-16T10:50:50.377+0000] {taskinstance.py:1956} INFO - Dependencies all met for dep_context=requeueable deps ti=<TaskInstance: dag1_test_production_summary.create_test_production_summary scheduled__2025-09-15T00:00:00+00:00 [queued]>
[2025-09-16T10:50:50.378+0000] {taskinstance.py:2170} INFO - Starting attempt 5 of 5
[2025-09-16T10:50:50.386+0000] {taskinstance.py:2191} INFO - Executing <Task(PythonOperator): create_test_production_summary> on 2025-09-15 00:00:00+00:00
[2025-09-16T10:50:50.391+0000] {standard_task_runner.py:60} INFO - Started process 233 to run task
[2025-09-16T10:50:50.395+0000] {standard_task_runner.py:87} INFO - Running: ['***', 'tasks', 'run', 'dag1_test_production_summary', 'create_test_production_summary', 'scheduled__2025-09-15T00:00:00+00:00', '--job-id', '10', '--raw', '--subdir', 'DAGS_FOLDER/sql_flow.py', '--cfg-path', '/tmp/tmp7zbw7y9j']
[2025-09-16T10:50:50.397+0000] {standard_task_runner.py:88} INFO - Job 10: Subtask create_test_production_summary
[2025-09-16T10:50:50.439+0000] {task_command.py:423} INFO - Running <TaskInstance: dag1_test_production_summary.create_test_production_summary scheduled__2025-09-15T00:00:00+00:00 [running]> on host 9bf7a2eb3ae2
[2025-09-16T10:50:50.487+0000] {taskinstance.py:2480} INFO - Exporting env vars: AIRFLOW_CTX_DAG_OWNER='***' AIRFLOW_CTX_DAG_ID='dag1_test_production_summary' AIRFLOW_CTX_TASK_ID='create_test_production_summary' AIRFLOW_CTX_EXECUTION_DATE='2025-09-15T00:00:00+00:00' AIRFLOW_CTX_TRY_NUMBER='5' AIRFLOW_CTX_DAG_RUN_ID='scheduled__2025-09-15T00:00:00+00:00'
[2025-09-16T10:50:50.541+0000] {logging_mixin.py:188} INFO - Error: column im.Route_Card_Journal does not exist
LINE 11:             ON pj."Route_Card_Journal" = im."Route_Card_Jour...
                                                  ^
HINT:  Perhaps you meant to reference the column "pj.Route_Card_Journal".
[2025-09-16T10:50:50.542+0000] {taskinstance.py:2698} ERROR - Task failed with exception
Traceback (most recent call last):
  File "/home/airflow/.local/lib/python3.8/site-packages/airflow/models/taskinstance.py", line 433, in _execute_task
    result = execute_callable(context=context, **execute_callable_kwargs)
  File "/home/airflow/.local/lib/python3.8/site-packages/airflow/operators/python.py", line 199, in execute
    return_value = self.execute_callable()
  File "/home/airflow/.local/lib/python3.8/site-packages/airflow/operators/python.py", line 216, in execute_callable
    return self.python_callable(*self.op_args, **self.op_kwargs)
  File "/opt/airflow/dags/sql_flow.py", line 38, in create_test_production_summary
    cursor.execute(create_view_query)
psycopg2.errors.UndefinedColumn: column im.Route_Card_Journal does not exist
LINE 11:             ON pj."Route_Card_Journal" = im."Route_Card_Jour...
                                                  ^
HINT:  Perhaps you meant to reference the column "pj.Route_Card_Journal".

[2025-09-16T10:50:50.552+0000] {taskinstance.py:1138} INFO - Marking task as FAILED. dag_id=dag1_test_production_summary, task_id=create_test_production_summary, execution_date=20250915T000000, start_date=20250916T105050, end_date=20250916T105050
[2025-09-16T10:50:50.562+0000] {standard_task_runner.py:107} ERROR - Failed to execute job 10 for task create_test_production_summary (column im.Route_Card_Journal does not exist
LINE 11:             ON pj."Route_Card_Journal" = im."Route_Card_Jour...
                                                  ^
HINT:  Perhaps you meant to reference the column "pj.Route_Card_Journal".
; 233)
[2025-09-16T10:50:50.607+0000] {local_task_job_runner.py:234} INFO - Task exited with return code 1
[2025-09-16T10:50:50.619+0000] {taskinstance.py:3280} INFO - 0 downstream tasks scheduled from follow-on schedule check
