[2025-09-16T10:38:13.423+0000] {taskinstance.py:1956} INFO - Dependencies all met for dep_context=non-requeueable deps ti=<TaskInstance: dag1_test_production_summary.create_test_production_summary scheduled__2025-09-15T00:00:00+00:00 [queued]>
[2025-09-16T10:38:13.427+0000] {taskinstance.py:1956} INFO - Dependencies all met for dep_context=requeueable deps ti=<TaskInstance: dag1_test_production_summary.create_test_production_summary scheduled__2025-09-15T00:00:00+00:00 [queued]>
[2025-09-16T10:38:13.429+0000] {taskinstance.py:2170} INFO - Starting attempt 1 of 1
[2025-09-16T10:38:13.437+0000] {taskinstance.py:2191} INFO - Executing <Task(PythonOperator): create_test_production_summary> on 2025-09-15 00:00:00+00:00
[2025-09-16T10:38:13.441+0000] {standard_task_runner.py:60} INFO - Started process 649 to run task
[2025-09-16T10:38:13.444+0000] {standard_task_runner.py:87} INFO - Running: ['***', 'tasks', 'run', 'dag1_test_production_summary', 'create_test_production_summary', 'scheduled__2025-09-15T00:00:00+00:00', '--job-id', '5', '--raw', '--subdir', 'DAGS_FOLDER/sql_flow.py', '--cfg-path', '/tmp/tmp6doyl63v']
[2025-09-16T10:38:13.446+0000] {standard_task_runner.py:88} INFO - Job 5: Subtask create_test_production_summary
[2025-09-16T10:38:13.485+0000] {task_command.py:423} INFO - Running <TaskInstance: dag1_test_production_summary.create_test_production_summary scheduled__2025-09-15T00:00:00+00:00 [running]> on host fc138b05e570
[2025-09-16T10:38:13.529+0000] {taskinstance.py:2480} INFO - Exporting env vars: AIRFLOW_CTX_DAG_OWNER='***' AIRFLOW_CTX_DAG_ID='dag1_test_production_summary' AIRFLOW_CTX_TASK_ID='create_test_production_summary' AIRFLOW_CTX_EXECUTION_DATE='2025-09-15T00:00:00+00:00' AIRFLOW_CTX_TRY_NUMBER='1' AIRFLOW_CTX_DAG_RUN_ID='scheduled__2025-09-15T00:00:00+00:00'
[2025-09-16T10:38:13.585+0000] {logging_mixin.py:188} INFO - Error: relation "production_journal" does not exist
LINE 9:         FROM Production_Journal pj
                     ^
[2025-09-16T10:38:13.588+0000] {python.py:201} INFO - Done. Returned value was: None
[2025-09-16T10:38:13.594+0000] {taskinstance.py:1138} INFO - Marking task as SUCCESS. dag_id=dag1_test_production_summary, task_id=create_test_production_summary, execution_date=20250915T000000, start_date=20250916T103813, end_date=20250916T103813
[2025-09-16T10:38:13.617+0000] {local_task_job_runner.py:234} INFO - Task exited with return code 0
[2025-09-16T10:38:13.628+0000] {taskinstance.py:3280} INFO - 0 downstream tasks scheduled from follow-on schedule check
[2025-09-16T10:41:59.642+0000] {taskinstance.py:1956} INFO - Dependencies all met for dep_context=non-requeueable deps ti=<TaskInstance: dag1_test_production_summary.create_test_production_summary scheduled__2025-09-15T00:00:00+00:00 [queued]>
[2025-09-16T10:41:59.646+0000] {taskinstance.py:1956} INFO - Dependencies all met for dep_context=requeueable deps ti=<TaskInstance: dag1_test_production_summary.create_test_production_summary scheduled__2025-09-15T00:00:00+00:00 [queued]>
[2025-09-16T10:41:59.646+0000] {taskinstance.py:2170} INFO - Starting attempt 1 of 1
[2025-09-16T10:41:59.655+0000] {taskinstance.py:2191} INFO - Executing <Task(PythonOperator): create_test_production_summary> on 2025-09-15 00:00:00+00:00
[2025-09-16T10:41:59.660+0000] {standard_task_runner.py:60} INFO - Started process 79 to run task
[2025-09-16T10:41:59.663+0000] {standard_task_runner.py:87} INFO - Running: ['***', 'tasks', 'run', 'dag1_test_production_summary', 'create_test_production_summary', 'scheduled__2025-09-15T00:00:00+00:00', '--job-id', '3', '--raw', '--subdir', 'DAGS_FOLDER/sql_flow.py', '--cfg-path', '/tmp/tmpk68hkq3a']
[2025-09-16T10:41:59.665+0000] {standard_task_runner.py:88} INFO - Job 3: Subtask create_test_production_summary
[2025-09-16T10:41:59.702+0000] {task_command.py:423} INFO - Running <TaskInstance: dag1_test_production_summary.create_test_production_summary scheduled__2025-09-15T00:00:00+00:00 [running]> on host 9bf7a2eb3ae2
[2025-09-16T10:41:59.749+0000] {taskinstance.py:2480} INFO - Exporting env vars: AIRFLOW_CTX_DAG_OWNER='***' AIRFLOW_CTX_DAG_ID='dag1_test_production_summary' AIRFLOW_CTX_TASK_ID='create_test_production_summary' AIRFLOW_CTX_EXECUTION_DATE='2025-09-15T00:00:00+00:00' AIRFLOW_CTX_TRY_NUMBER='1' AIRFLOW_CTX_DAG_RUN_ID='scheduled__2025-09-15T00:00:00+00:00'
[2025-09-16T10:41:59.804+0000] {logging_mixin.py:188} INFO - Error: syntax error at or near "<"
LINE 1:  <SQL ด้านบน> 
         ^
[2025-09-16T10:41:59.805+0000] {taskinstance.py:2698} ERROR - Task failed with exception
Traceback (most recent call last):
  File "/home/airflow/.local/lib/python3.8/site-packages/airflow/models/taskinstance.py", line 433, in _execute_task
    result = execute_callable(context=context, **execute_callable_kwargs)
  File "/home/airflow/.local/lib/python3.8/site-packages/airflow/operators/python.py", line 199, in execute
    return_value = self.execute_callable()
  File "/home/airflow/.local/lib/python3.8/site-packages/airflow/operators/python.py", line 216, in execute_callable
    return self.python_callable(*self.op_args, **self.op_kwargs)
  File "/opt/airflow/dags/sql_flow.py", line 22, in create_test_production_summary
    cursor.execute(create_view_query)
psycopg2.errors.SyntaxError: syntax error at or near "<"
LINE 1:  <SQL ด้านบน> 
         ^

[2025-09-16T10:41:59.815+0000] {taskinstance.py:1138} INFO - Marking task as FAILED. dag_id=dag1_test_production_summary, task_id=create_test_production_summary, execution_date=20250915T000000, start_date=20250916T104159, end_date=20250916T104159
[2025-09-16T10:41:59.825+0000] {standard_task_runner.py:107} ERROR - Failed to execute job 3 for task create_test_production_summary (syntax error at or near "<"
LINE 1:  <SQL ด้านบน> 
         ^
; 79)
[2025-09-16T10:41:59.836+0000] {local_task_job_runner.py:234} INFO - Task exited with return code 1
[2025-09-16T10:41:59.847+0000] {taskinstance.py:3280} INFO - 0 downstream tasks scheduled from follow-on schedule check
[2025-09-16T10:53:29.405+0000] {taskinstance.py:1956} INFO - Dependencies all met for dep_context=non-requeueable deps ti=<TaskInstance: dag1_test_production_summary.create_test_production_summary scheduled__2025-09-15T00:00:00+00:00 [queued]>
[2025-09-16T10:53:29.410+0000] {taskinstance.py:1956} INFO - Dependencies all met for dep_context=requeueable deps ti=<TaskInstance: dag1_test_production_summary.create_test_production_summary scheduled__2025-09-15T00:00:00+00:00 [queued]>
[2025-09-16T10:53:29.410+0000] {taskinstance.py:2170} INFO - Starting attempt 1 of 1
[2025-09-16T10:53:29.417+0000] {taskinstance.py:2191} INFO - Executing <Task(PythonOperator): create_test_production_summary> on 2025-09-15 00:00:00+00:00
[2025-09-16T10:53:29.421+0000] {standard_task_runner.py:60} INFO - Started process 96 to run task
[2025-09-16T10:53:29.424+0000] {standard_task_runner.py:87} INFO - Running: ['***', 'tasks', 'run', 'dag1_test_production_summary', 'create_test_production_summary', 'scheduled__2025-09-15T00:00:00+00:00', '--job-id', '4', '--raw', '--subdir', 'DAGS_FOLDER/sql_flow.py', '--cfg-path', '/tmp/tmpxgi5rr37']
[2025-09-16T10:53:29.427+0000] {standard_task_runner.py:88} INFO - Job 4: Subtask create_test_production_summary
[2025-09-16T10:53:29.467+0000] {task_command.py:423} INFO - Running <TaskInstance: dag1_test_production_summary.create_test_production_summary scheduled__2025-09-15T00:00:00+00:00 [running]> on host 76e4aae73331
[2025-09-16T10:53:29.517+0000] {taskinstance.py:2480} INFO - Exporting env vars: AIRFLOW_CTX_DAG_OWNER='***' AIRFLOW_CTX_DAG_ID='dag1_test_production_summary' AIRFLOW_CTX_TASK_ID='create_test_production_summary' AIRFLOW_CTX_EXECUTION_DATE='2025-09-15T00:00:00+00:00' AIRFLOW_CTX_TRY_NUMBER='1' AIRFLOW_CTX_DAG_RUN_ID='scheduled__2025-09-15T00:00:00+00:00'
[2025-09-16T10:53:29.571+0000] {logging_mixin.py:188} INFO - Error: column im.Route_Card_Journal does not exist
LINE 11:             ON pj."Route_Card_Journal" = im."Route_Card_Jour...
                                                  ^
HINT:  Perhaps you meant to reference the column "pj.Route_Card_Journal".
[2025-09-16T10:53:29.571+0000] {taskinstance.py:2698} ERROR - Task failed with exception
Traceback (most recent call last):
  File "/home/airflow/.local/lib/python3.8/site-packages/airflow/models/taskinstance.py", line 433, in _execute_task
    result = execute_callable(context=context, **execute_callable_kwargs)
  File "/home/airflow/.local/lib/python3.8/site-packages/airflow/operators/python.py", line 199, in execute
    return_value = self.execute_callable()
  File "/home/airflow/.local/lib/python3.8/site-packages/airflow/operators/python.py", line 216, in execute_callable
    return self.python_callable(*self.op_args, **self.op_kwargs)
  File "/opt/airflow/dags/sql_flow.py", line 38, in create_test_production_summary
    cursor.execute(create_view_query)
psycopg2.errors.UndefinedColumn: column im.Route_Card_Journal does not exist
LINE 11:             ON pj."Route_Card_Journal" = im."Route_Card_Jour...
                                                  ^
HINT:  Perhaps you meant to reference the column "pj.Route_Card_Journal".

[2025-09-16T10:53:29.582+0000] {taskinstance.py:1138} INFO - Marking task as FAILED. dag_id=dag1_test_production_summary, task_id=create_test_production_summary, execution_date=20250915T000000, start_date=20250916T105329, end_date=20250916T105329
[2025-09-16T10:53:29.592+0000] {standard_task_runner.py:107} ERROR - Failed to execute job 4 for task create_test_production_summary (column im.Route_Card_Journal does not exist
LINE 11:             ON pj."Route_Card_Journal" = im."Route_Card_Jour...
                                                  ^
HINT:  Perhaps you meant to reference the column "pj.Route_Card_Journal".
; 96)
[2025-09-16T10:53:29.637+0000] {local_task_job_runner.py:234} INFO - Task exited with return code 1
[2025-09-16T10:53:29.649+0000] {taskinstance.py:3280} INFO - 0 downstream tasks scheduled from follow-on schedule check
[2025-09-16T10:57:28.023+0000] {taskinstance.py:1956} INFO - Dependencies all met for dep_context=non-requeueable deps ti=<TaskInstance: dag1_test_production_summary.create_test_production_summary scheduled__2025-09-15T00:00:00+00:00 [queued]>
[2025-09-16T10:57:28.027+0000] {taskinstance.py:1956} INFO - Dependencies all met for dep_context=requeueable deps ti=<TaskInstance: dag1_test_production_summary.create_test_production_summary scheduled__2025-09-15T00:00:00+00:00 [queued]>
[2025-09-16T10:57:28.028+0000] {taskinstance.py:2170} INFO - Starting attempt 1 of 1
[2025-09-16T10:57:28.039+0000] {taskinstance.py:2191} INFO - Executing <Task(PythonOperator): create_test_production_summary> on 2025-09-15 00:00:00+00:00
[2025-09-16T10:57:28.043+0000] {standard_task_runner.py:60} INFO - Started process 80 to run task
[2025-09-16T10:57:28.046+0000] {standard_task_runner.py:87} INFO - Running: ['***', 'tasks', 'run', 'dag1_test_production_summary', 'create_test_production_summary', 'scheduled__2025-09-15T00:00:00+00:00', '--job-id', '4', '--raw', '--subdir', 'DAGS_FOLDER/sql_flow.py', '--cfg-path', '/tmp/tmppmf92q09']
[2025-09-16T10:57:28.050+0000] {standard_task_runner.py:88} INFO - Job 4: Subtask create_test_production_summary
[2025-09-16T10:57:28.092+0000] {task_command.py:423} INFO - Running <TaskInstance: dag1_test_production_summary.create_test_production_summary scheduled__2025-09-15T00:00:00+00:00 [running]> on host c6016013c48b
[2025-09-16T10:57:28.139+0000] {taskinstance.py:2480} INFO - Exporting env vars: AIRFLOW_CTX_DAG_OWNER='***' AIRFLOW_CTX_DAG_ID='dag1_test_production_summary' AIRFLOW_CTX_TASK_ID='create_test_production_summary' AIRFLOW_CTX_EXECUTION_DATE='2025-09-15T00:00:00+00:00' AIRFLOW_CTX_TRY_NUMBER='1' AIRFLOW_CTX_DAG_RUN_ID='scheduled__2025-09-15T00:00:00+00:00'
[2025-09-16T10:57:28.182+0000] {logging_mixin.py:188} INFO - Error: column dt.Route_Card_Journal does not exist
LINE 11:             ON pj."Route_Card_Journal" = dt."Route_Card_Jour...
                                                  ^
HINT:  Perhaps you meant to reference the column "dt.Route_Card_Jounal".
[2025-09-16T10:57:28.182+0000] {taskinstance.py:2698} ERROR - Task failed with exception
Traceback (most recent call last):
  File "/home/airflow/.local/lib/python3.8/site-packages/airflow/models/taskinstance.py", line 433, in _execute_task
    result = execute_callable(context=context, **execute_callable_kwargs)
  File "/home/airflow/.local/lib/python3.8/site-packages/airflow/operators/python.py", line 199, in execute
    return_value = self.execute_callable()
  File "/home/airflow/.local/lib/python3.8/site-packages/airflow/operators/python.py", line 216, in execute_callable
    return self.python_callable(*self.op_args, **self.op_kwargs)
  File "/opt/airflow/dags/sql_flow.py", line 38, in create_test_production_summary
    cursor.execute(create_view_query)
psycopg2.errors.UndefinedColumn: column dt.Route_Card_Journal does not exist
LINE 11:             ON pj."Route_Card_Journal" = dt."Route_Card_Jour...
                                                  ^
HINT:  Perhaps you meant to reference the column "dt.Route_Card_Jounal".

[2025-09-16T10:57:28.191+0000] {taskinstance.py:1138} INFO - Marking task as FAILED. dag_id=dag1_test_production_summary, task_id=create_test_production_summary, execution_date=20250915T000000, start_date=20250916T105728, end_date=20250916T105728
[2025-09-16T10:57:28.206+0000] {standard_task_runner.py:107} ERROR - Failed to execute job 4 for task create_test_production_summary (column dt.Route_Card_Journal does not exist
LINE 11:             ON pj."Route_Card_Journal" = dt."Route_Card_Jour...
                                                  ^
HINT:  Perhaps you meant to reference the column "dt.Route_Card_Jounal".
; 80)
[2025-09-16T10:57:28.219+0000] {local_task_job_runner.py:234} INFO - Task exited with return code 1
[2025-09-16T10:57:28.229+0000] {taskinstance.py:3280} INFO - 0 downstream tasks scheduled from follow-on schedule check
