[2025-09-18T04:56:56.940+0000] {taskinstance.py:1956} INFO - Dependencies all met for dep_context=non-requeueable deps ti=<TaskInstance: dag_production_summary_with_oee.create_view_jobcard_merged manual__2025-09-18T04:56:55.095339+00:00 [queued]>
[2025-09-18T04:56:56.947+0000] {taskinstance.py:1956} INFO - Dependencies all met for dep_context=requeueable deps ti=<TaskInstance: dag_production_summary_with_oee.create_view_jobcard_merged manual__2025-09-18T04:56:55.095339+00:00 [queued]>
[2025-09-18T04:56:56.947+0000] {taskinstance.py:2170} INFO - Starting attempt 1 of 1
[2025-09-18T04:56:56.955+0000] {taskinstance.py:2191} INFO - Executing <Task(PythonOperator): create_view_jobcard_merged> on 2025-09-18 04:56:55.095339+00:00
[2025-09-18T04:56:56.959+0000] {standard_task_runner.py:60} INFO - Started process 79 to run task
[2025-09-18T04:56:56.963+0000] {standard_task_runner.py:87} INFO - Running: ['***', 'tasks', 'run', 'dag_production_summary_with_oee', 'create_view_jobcard_merged', 'manual__2025-09-18T04:56:55.095339+00:00', '--job-id', '3', '--raw', '--subdir', 'DAGS_FOLDER/sql_flow.py', '--cfg-path', '/tmp/tmppo1rzoak']
[2025-09-18T04:56:56.966+0000] {standard_task_runner.py:88} INFO - Job 3: Subtask create_view_jobcard_merged
[2025-09-18T04:56:57.004+0000] {task_command.py:423} INFO - Running <TaskInstance: dag_production_summary_with_oee.create_view_jobcard_merged manual__2025-09-18T04:56:55.095339+00:00 [running]> on host 9be99ad8a67b
[2025-09-18T04:56:57.051+0000] {taskinstance.py:2480} INFO - Exporting env vars: AIRFLOW_CTX_DAG_OWNER='***' AIRFLOW_CTX_DAG_ID='dag_production_summary_with_oee' AIRFLOW_CTX_TASK_ID='create_view_jobcard_merged' AIRFLOW_CTX_EXECUTION_DATE='2025-09-18T04:56:55.095339+00:00' AIRFLOW_CTX_TRY_NUMBER='1' AIRFLOW_CTX_DAG_RUN_ID='manual__2025-09-18T04:56:55.095339+00:00'
[2025-09-18T04:56:57.110+0000] {logging_mixin.py:188} INFO - ‚ùå Error (create_view_jobcard_merged): relation "job_card" does not exist
LINE 9:             FROM job_card
                         ^
[2025-09-18T04:56:57.110+0000] {taskinstance.py:2698} ERROR - Task failed with exception
Traceback (most recent call last):
  File "/home/airflow/.local/lib/python3.8/site-packages/airflow/models/taskinstance.py", line 433, in _execute_task
    result = execute_callable(context=context, **execute_callable_kwargs)
  File "/home/airflow/.local/lib/python3.8/site-packages/airflow/operators/python.py", line 199, in execute
    return_value = self.execute_callable()
  File "/home/airflow/.local/lib/python3.8/site-packages/airflow/operators/python.py", line 216, in execute_callable
    return self.python_callable(*self.op_args, **self.op_kwargs)
  File "/opt/airflow/dags/sql_flow.py", line 360, in create_view_jobcard_merged
    cursor.execute(create_view_query)
psycopg2.errors.UndefinedTable: relation "job_card" does not exist
LINE 9:             FROM job_card
                         ^

[2025-09-18T04:56:57.120+0000] {taskinstance.py:1138} INFO - Marking task as FAILED. dag_id=dag_production_summary_with_oee, task_id=create_view_jobcard_merged, execution_date=20250918T045655, start_date=20250918T045656, end_date=20250918T045657
[2025-09-18T04:56:57.128+0000] {standard_task_runner.py:107} ERROR - Failed to execute job 3 for task create_view_jobcard_merged (relation "job_card" does not exist
LINE 9:             FROM job_card
                         ^
; 79)
[2025-09-18T04:56:57.135+0000] {local_task_job_runner.py:234} INFO - Task exited with return code 1
[2025-09-18T04:56:57.149+0000] {taskinstance.py:3280} INFO - 0 downstream tasks scheduled from follow-on schedule check
