[2025-09-24T09:09:37.854+0000] {taskinstance.py:1956} INFO - Dependencies all met for dep_context=non-requeueable deps ti=<TaskInstance: dag_data_cleanse_and_calculate_all.cleanse_data_h10 manual__2025-09-24T09:09:29.387528+00:00 [queued]>
[2025-09-24T09:09:37.863+0000] {taskinstance.py:1956} INFO - Dependencies all met for dep_context=requeueable deps ti=<TaskInstance: dag_data_cleanse_and_calculate_all.cleanse_data_h10 manual__2025-09-24T09:09:29.387528+00:00 [queued]>
[2025-09-24T09:09:37.864+0000] {taskinstance.py:2170} INFO - Starting attempt 1 of 1
[2025-09-24T09:09:37.874+0000] {taskinstance.py:2191} INFO - Executing <Task(PythonOperator): cleanse_data_h10> on 2025-09-24 09:09:29.387528+00:00
[2025-09-24T09:09:37.878+0000] {standard_task_runner.py:60} INFO - Started process 1711 to run task
[2025-09-24T09:09:37.881+0000] {standard_task_runner.py:87} INFO - Running: ['***', 'tasks', 'run', 'dag_data_cleanse_and_calculate_all', 'cleanse_data_h10', 'manual__2025-09-24T09:09:29.387528+00:00', '--job-id', '270', '--raw', '--subdir', 'DAGS_FOLDER/cleansing_data_flow.py', '--cfg-path', '/tmp/tmp9f3yd0rr']
[2025-09-24T09:09:37.882+0000] {standard_task_runner.py:88} INFO - Job 270: Subtask cleanse_data_h10
[2025-09-24T09:09:37.925+0000] {task_command.py:423} INFO - Running <TaskInstance: dag_data_cleanse_and_calculate_all.cleanse_data_h10 manual__2025-09-24T09:09:29.387528+00:00 [running]> on host feaba2204362
[2025-09-24T09:09:37.978+0000] {taskinstance.py:2480} INFO - Exporting env vars: AIRFLOW_CTX_DAG_OWNER='***' AIRFLOW_CTX_DAG_ID='dag_data_cleanse_and_calculate_all' AIRFLOW_CTX_TASK_ID='cleanse_data_h10' AIRFLOW_CTX_EXECUTION_DATE='2025-09-24T09:09:29.387528+00:00' AIRFLOW_CTX_TRY_NUMBER='1' AIRFLOW_CTX_DAG_RUN_ID='manual__2025-09-24T09:09:29.387528+00:00'
[2025-09-24T09:09:38.055+0000] {taskinstance.py:2698} ERROR - Task failed with exception
Traceback (most recent call last):
  File "/home/airflow/.local/lib/python3.8/site-packages/airflow/models/taskinstance.py", line 433, in _execute_task
    result = execute_callable(context=context, **execute_callable_kwargs)
  File "/home/airflow/.local/lib/python3.8/site-packages/airflow/operators/python.py", line 199, in execute
    return_value = self.execute_callable()
  File "/home/airflow/.local/lib/python3.8/site-packages/airflow/operators/python.py", line 216, in execute_callable
    return self.python_callable(*self.op_args, **self.op_kwargs)
  File "/opt/airflow/dags/cleansing_data_flow.py", line 1612, in cleanse_data
    cursor.execute(insert_query, (
psycopg2.errors.StringDataRightTruncation: value too long for type character(1)

[2025-09-24T09:09:38.067+0000] {taskinstance.py:1138} INFO - Marking task as FAILED. dag_id=dag_data_cleanse_and_calculate_all, task_id=cleanse_data_h10, execution_date=20250924T090929, start_date=20250924T090937, end_date=20250924T090938
[2025-09-24T09:09:38.077+0000] {standard_task_runner.py:107} ERROR - Failed to execute job 270 for task cleanse_data_h10 (value too long for type character(1)
; 1711)
[2025-09-24T09:09:38.093+0000] {local_task_job_runner.py:234} INFO - Task exited with return code 1
[2025-09-24T09:09:38.109+0000] {taskinstance.py:3280} INFO - 0 downstream tasks scheduled from follow-on schedule check
