[2025-09-24T03:21:24.107+0000] {taskinstance.py:1956} INFO - Dependencies all met for dep_context=non-requeueable deps ti=<TaskInstance: dag_mockup_test_raw_data_2.insert_mock_data_c8 scheduled__2025-09-24T02:00:00+00:00 [queued]>
[2025-09-24T03:21:24.115+0000] {taskinstance.py:1956} INFO - Dependencies all met for dep_context=requeueable deps ti=<TaskInstance: dag_mockup_test_raw_data_2.insert_mock_data_c8 scheduled__2025-09-24T02:00:00+00:00 [queued]>
[2025-09-24T03:21:24.116+0000] {taskinstance.py:2170} INFO - Starting attempt 1 of 1
[2025-09-24T03:21:24.138+0000] {taskinstance.py:2191} INFO - Executing <Task(PythonOperator): insert_mock_data_c8> on 2025-09-24 02:00:00+00:00
[2025-09-24T03:21:24.147+0000] {standard_task_runner.py:60} INFO - Started process 111 to run task
[2025-09-24T03:21:24.158+0000] {standard_task_runner.py:87} INFO - Running: ['***', 'tasks', 'run', 'dag_mockup_test_raw_data_2', 'insert_mock_data_c8', 'scheduled__2025-09-24T02:00:00+00:00', '--job-id', '11', '--raw', '--subdir', 'DAGS_FOLDER/moc_data_flow_2.py', '--cfg-path', '/tmp/tmpuauph32g']
[2025-09-24T03:21:24.168+0000] {standard_task_runner.py:88} INFO - Job 11: Subtask insert_mock_data_c8
[2025-09-24T03:21:24.342+0000] {task_command.py:423} INFO - Running <TaskInstance: dag_mockup_test_raw_data_2.insert_mock_data_c8 scheduled__2025-09-24T02:00:00+00:00 [running]> on host 0fddc9cfe86c
[2025-09-24T03:21:24.488+0000] {taskinstance.py:2480} INFO - Exporting env vars: AIRFLOW_CTX_DAG_OWNER='***' AIRFLOW_CTX_DAG_ID='dag_mockup_test_raw_data_2' AIRFLOW_CTX_TASK_ID='insert_mock_data_c8' AIRFLOW_CTX_EXECUTION_DATE='2025-09-24T02:00:00+00:00' AIRFLOW_CTX_TRY_NUMBER='1' AIRFLOW_CTX_DAG_RUN_ID='scheduled__2025-09-24T02:00:00+00:00'
[2025-09-24T03:21:24.636+0000] {taskinstance.py:2698} ERROR - Task failed with exception
Traceback (most recent call last):
  File "/home/airflow/.local/lib/python3.8/site-packages/airflow/models/taskinstance.py", line 433, in _execute_task
    result = execute_callable(context=context, **execute_callable_kwargs)
  File "/home/airflow/.local/lib/python3.8/site-packages/airflow/operators/python.py", line 199, in execute
    return_value = self.execute_callable()
  File "/home/airflow/.local/lib/python3.8/site-packages/airflow/operators/python.py", line 216, in execute_callable
    return self.python_callable(*self.op_args, **self.op_kwargs)
  File "/opt/airflow/dags/moc_data_flow_2.py", line 462, in insert_mock_data_c8
    cursor.execute(
psycopg2.errors.NotNullViolation: null value in column "id" of relation "test_raw_data_c8" violates not-null constraint
DETAIL:  Failing row contains (null, 2.89, 1.99, 120, 129, 96, 76, RUN                 , 2025-09-24 03:21:24.619577).

[2025-09-24T03:21:24.653+0000] {taskinstance.py:1138} INFO - Marking task as FAILED. dag_id=dag_mockup_test_raw_data_2, task_id=insert_mock_data_c8, execution_date=20250924T020000, start_date=20250924T032124, end_date=20250924T032124
[2025-09-24T03:21:24.693+0000] {standard_task_runner.py:107} ERROR - Failed to execute job 11 for task insert_mock_data_c8 (null value in column "id" of relation "test_raw_data_c8" violates not-null constraint
DETAIL:  Failing row contains (null, 2.89, 1.99, 120, 129, 96, 76, RUN                 , 2025-09-24 03:21:24.619577).
; 111)
[2025-09-24T03:21:24.754+0000] {local_task_job_runner.py:234} INFO - Task exited with return code 1
[2025-09-24T03:21:24.879+0000] {taskinstance.py:3280} INFO - 0 downstream tasks scheduled from follow-on schedule check
