[2025-09-18T01:19:21.895+0000] {taskinstance.py:1956} INFO - Dependencies all met for dep_context=non-requeueable deps ti=<TaskInstance: dag_production_summary_with_oee.create_oee_a2 scheduled__2025-09-17T00:00:00+00:00 [queued]>
[2025-09-18T01:19:21.900+0000] {taskinstance.py:1956} INFO - Dependencies all met for dep_context=requeueable deps ti=<TaskInstance: dag_production_summary_with_oee.create_oee_a2 scheduled__2025-09-17T00:00:00+00:00 [queued]>
[2025-09-18T01:19:21.901+0000] {taskinstance.py:2170} INFO - Starting attempt 1 of 1
[2025-09-18T01:19:21.909+0000] {taskinstance.py:2191} INFO - Executing <Task(PythonOperator): create_oee_a2> on 2025-09-17 00:00:00+00:00
[2025-09-18T01:19:21.913+0000] {standard_task_runner.py:60} INFO - Started process 86 to run task
[2025-09-18T01:19:21.915+0000] {standard_task_runner.py:87} INFO - Running: ['***', 'tasks', 'run', 'dag_production_summary_with_oee', 'create_oee_a2', 'scheduled__2025-09-17T00:00:00+00:00', '--job-id', '6', '--raw', '--subdir', 'DAGS_FOLDER/sql_flow.py', '--cfg-path', '/tmp/tmpkkyjyi83']
[2025-09-18T01:19:21.917+0000] {standard_task_runner.py:88} INFO - Job 6: Subtask create_oee_a2
[2025-09-18T01:19:21.953+0000] {task_command.py:423} INFO - Running <TaskInstance: dag_production_summary_with_oee.create_oee_a2 scheduled__2025-09-17T00:00:00+00:00 [running]> on host d11e6b327003
[2025-09-18T01:19:21.995+0000] {taskinstance.py:2480} INFO - Exporting env vars: AIRFLOW_CTX_DAG_OWNER='***' AIRFLOW_CTX_DAG_ID='dag_production_summary_with_oee' AIRFLOW_CTX_TASK_ID='create_oee_a2' AIRFLOW_CTX_EXECUTION_DATE='2025-09-17T00:00:00+00:00' AIRFLOW_CTX_TRY_NUMBER='1' AIRFLOW_CTX_DAG_RUN_ID='scheduled__2025-09-17T00:00:00+00:00'
[2025-09-18T01:19:22.040+0000] {logging_mixin.py:188} INFO - ❌ Error: relation "Test_Production_summary" does not exist
LINE 12:         FROM "Test_Production_summary";
                      ^
[2025-09-18T01:19:22.041+0000] {taskinstance.py:2698} ERROR - Task failed with exception
Traceback (most recent call last):
  File "/home/airflow/.local/lib/python3.8/site-packages/airflow/models/taskinstance.py", line 433, in _execute_task
    result = execute_callable(context=context, **execute_callable_kwargs)
  File "/home/airflow/.local/lib/python3.8/site-packages/airflow/operators/python.py", line 199, in execute
    return_value = self.execute_callable()
  File "/home/airflow/.local/lib/python3.8/site-packages/airflow/operators/python.py", line 216, in execute_callable
    return self.python_callable(*self.op_args, **self.op_kwargs)
  File "/opt/airflow/dags/sql_flow.py", line 227, in create_oee_a2
    cursor.execute(create_view_query)
psycopg2.errors.UndefinedTable: relation "Test_Production_summary" does not exist
LINE 12:         FROM "Test_Production_summary";
                      ^

[2025-09-18T01:19:22.050+0000] {taskinstance.py:1138} INFO - Marking task as FAILED. dag_id=dag_production_summary_with_oee, task_id=create_oee_a2, execution_date=20250917T000000, start_date=20250918T011921, end_date=20250918T011922
[2025-09-18T01:19:22.060+0000] {standard_task_runner.py:107} ERROR - Failed to execute job 6 for task create_oee_a2 (relation "Test_Production_summary" does not exist
LINE 12:         FROM "Test_Production_summary";
                      ^
; 86)
[2025-09-18T01:19:22.087+0000] {local_task_job_runner.py:234} INFO - Task exited with return code 1
[2025-09-18T01:19:22.098+0000] {taskinstance.py:3280} INFO - 0 downstream tasks scheduled from follow-on schedule check
[2025-09-18T01:35:36.613+0000] {taskinstance.py:1956} INFO - Dependencies all met for dep_context=non-requeueable deps ti=<TaskInstance: dag_production_summary_with_oee.create_oee_a2 scheduled__2025-09-17T00:00:00+00:00 [queued]>
[2025-09-18T01:35:36.618+0000] {taskinstance.py:1956} INFO - Dependencies all met for dep_context=requeueable deps ti=<TaskInstance: dag_production_summary_with_oee.create_oee_a2 scheduled__2025-09-17T00:00:00+00:00 [queued]>
[2025-09-18T01:35:36.619+0000] {taskinstance.py:2170} INFO - Starting attempt 1 of 1
[2025-09-18T01:35:36.629+0000] {taskinstance.py:2191} INFO - Executing <Task(PythonOperator): create_oee_a2> on 2025-09-17 00:00:00+00:00
[2025-09-18T01:35:36.632+0000] {standard_task_runner.py:60} INFO - Started process 86 to run task
[2025-09-18T01:35:36.634+0000] {standard_task_runner.py:87} INFO - Running: ['***', 'tasks', 'run', 'dag_production_summary_with_oee', 'create_oee_a2', 'scheduled__2025-09-17T00:00:00+00:00', '--job-id', '6', '--raw', '--subdir', 'DAGS_FOLDER/sql_flow.py', '--cfg-path', '/tmp/tmpp_sbw62r']
[2025-09-18T01:35:36.636+0000] {standard_task_runner.py:88} INFO - Job 6: Subtask create_oee_a2
[2025-09-18T01:35:36.672+0000] {task_command.py:423} INFO - Running <TaskInstance: dag_production_summary_with_oee.create_oee_a2 scheduled__2025-09-17T00:00:00+00:00 [running]> on host e601ccdb5885
[2025-09-18T01:35:36.717+0000] {taskinstance.py:2480} INFO - Exporting env vars: AIRFLOW_CTX_DAG_OWNER='***' AIRFLOW_CTX_DAG_ID='dag_production_summary_with_oee' AIRFLOW_CTX_TASK_ID='create_oee_a2' AIRFLOW_CTX_EXECUTION_DATE='2025-09-17T00:00:00+00:00' AIRFLOW_CTX_TRY_NUMBER='1' AIRFLOW_CTX_DAG_RUN_ID='scheduled__2025-09-17T00:00:00+00:00'
[2025-09-18T01:35:36.776+0000] {logging_mixin.py:188} INFO - ❌ Error (create_oee_a2): column "Line" does not exist
LINE 5:             "Line",
                    ^
[2025-09-18T01:35:36.777+0000] {taskinstance.py:2698} ERROR - Task failed with exception
Traceback (most recent call last):
  File "/home/airflow/.local/lib/python3.8/site-packages/airflow/models/taskinstance.py", line 433, in _execute_task
    result = execute_callable(context=context, **execute_callable_kwargs)
  File "/home/airflow/.local/lib/python3.8/site-packages/airflow/operators/python.py", line 199, in execute
    return_value = self.execute_callable()
  File "/home/airflow/.local/lib/python3.8/site-packages/airflow/operators/python.py", line 216, in execute_callable
    return self.python_callable(*self.op_args, **self.op_kwargs)
  File "/opt/airflow/dags/sql_flow.py", line 263, in create_oee_a2
    cursor.execute(create_view_query)
psycopg2.errors.UndefinedColumn: column "Line" does not exist
LINE 5:             "Line",
                    ^

[2025-09-18T01:35:36.786+0000] {taskinstance.py:1138} INFO - Marking task as FAILED. dag_id=dag_production_summary_with_oee, task_id=create_oee_a2, execution_date=20250917T000000, start_date=20250918T013536, end_date=20250918T013536
[2025-09-18T01:35:36.796+0000] {standard_task_runner.py:107} ERROR - Failed to execute job 6 for task create_oee_a2 (column "Line" does not exist
LINE 5:             "Line",
                    ^
; 86)
[2025-09-18T01:35:36.807+0000] {local_task_job_runner.py:234} INFO - Task exited with return code 1
[2025-09-18T01:35:36.818+0000] {taskinstance.py:3280} INFO - 0 downstream tasks scheduled from follow-on schedule check
[2025-09-18T01:39:26.289+0000] {taskinstance.py:1956} INFO - Dependencies all met for dep_context=non-requeueable deps ti=<TaskInstance: dag_production_summary_with_oee.create_oee_a2 scheduled__2025-09-17T00:00:00+00:00 [queued]>
[2025-09-18T01:39:26.294+0000] {taskinstance.py:1956} INFO - Dependencies all met for dep_context=requeueable deps ti=<TaskInstance: dag_production_summary_with_oee.create_oee_a2 scheduled__2025-09-17T00:00:00+00:00 [queued]>
[2025-09-18T01:39:26.294+0000] {taskinstance.py:2170} INFO - Starting attempt 1 of 1
[2025-09-18T01:39:26.301+0000] {taskinstance.py:2191} INFO - Executing <Task(PythonOperator): create_oee_a2> on 2025-09-17 00:00:00+00:00
[2025-09-18T01:39:26.304+0000] {standard_task_runner.py:60} INFO - Started process 86 to run task
[2025-09-18T01:39:26.308+0000] {standard_task_runner.py:87} INFO - Running: ['***', 'tasks', 'run', 'dag_production_summary_with_oee', 'create_oee_a2', 'scheduled__2025-09-17T00:00:00+00:00', '--job-id', '6', '--raw', '--subdir', 'DAGS_FOLDER/sql_flow.py', '--cfg-path', '/tmp/tmpgz3hzfkd']
[2025-09-18T01:39:26.310+0000] {standard_task_runner.py:88} INFO - Job 6: Subtask create_oee_a2
[2025-09-18T01:39:26.352+0000] {task_command.py:423} INFO - Running <TaskInstance: dag_production_summary_with_oee.create_oee_a2 scheduled__2025-09-17T00:00:00+00:00 [running]> on host 73605eba340c
[2025-09-18T01:39:26.398+0000] {taskinstance.py:2480} INFO - Exporting env vars: AIRFLOW_CTX_DAG_OWNER='***' AIRFLOW_CTX_DAG_ID='dag_production_summary_with_oee' AIRFLOW_CTX_TASK_ID='create_oee_a2' AIRFLOW_CTX_EXECUTION_DATE='2025-09-17T00:00:00+00:00' AIRFLOW_CTX_TRY_NUMBER='1' AIRFLOW_CTX_DAG_RUN_ID='scheduled__2025-09-17T00:00:00+00:00'
[2025-09-18T01:39:26.460+0000] {logging_mixin.py:188} INFO - View OEE_A2 ถูกสร้างแล้ว
[2025-09-18T01:39:26.461+0000] {python.py:201} INFO - Done. Returned value was: None
[2025-09-18T01:39:26.466+0000] {taskinstance.py:1138} INFO - Marking task as SUCCESS. dag_id=dag_production_summary_with_oee, task_id=create_oee_a2, execution_date=20250917T000000, start_date=20250918T013926, end_date=20250918T013926
[2025-09-18T01:39:26.480+0000] {local_task_job_runner.py:234} INFO - Task exited with return code 0
[2025-09-18T01:39:26.490+0000] {taskinstance.py:3280} INFO - 0 downstream tasks scheduled from follow-on schedule check
