[2025-09-16T10:57:28.018+0000] {taskinstance.py:1956} INFO - Dependencies all met for dep_context=non-requeueable deps ti=<TaskInstance: dag1_test_production_summary.create_test_production_summary manual__2025-09-16T10:57:25.974337+00:00 [queued]>
[2025-09-16T10:57:28.023+0000] {taskinstance.py:1956} INFO - Dependencies all met for dep_context=requeueable deps ti=<TaskInstance: dag1_test_production_summary.create_test_production_summary manual__2025-09-16T10:57:25.974337+00:00 [queued]>
[2025-09-16T10:57:28.023+0000] {taskinstance.py:2170} INFO - Starting attempt 1 of 1
[2025-09-16T10:57:28.031+0000] {taskinstance.py:2191} INFO - Executing <Task(PythonOperator): create_test_production_summary> on 2025-09-16 10:57:25.974337+00:00
[2025-09-16T10:57:28.038+0000] {standard_task_runner.py:60} INFO - Started process 79 to run task
[2025-09-16T10:57:28.041+0000] {standard_task_runner.py:87} INFO - Running: ['***', 'tasks', 'run', 'dag1_test_production_summary', 'create_test_production_summary', 'manual__2025-09-16T10:57:25.974337+00:00', '--job-id', '3', '--raw', '--subdir', 'DAGS_FOLDER/sql_flow.py', '--cfg-path', '/tmp/tmpqueo6zt7']
[2025-09-16T10:57:28.044+0000] {standard_task_runner.py:88} INFO - Job 3: Subtask create_test_production_summary
[2025-09-16T10:57:28.087+0000] {task_command.py:423} INFO - Running <TaskInstance: dag1_test_production_summary.create_test_production_summary manual__2025-09-16T10:57:25.974337+00:00 [running]> on host c6016013c48b
[2025-09-16T10:57:28.137+0000] {taskinstance.py:2480} INFO - Exporting env vars: AIRFLOW_CTX_DAG_OWNER='***' AIRFLOW_CTX_DAG_ID='dag1_test_production_summary' AIRFLOW_CTX_TASK_ID='create_test_production_summary' AIRFLOW_CTX_EXECUTION_DATE='2025-09-16T10:57:25.974337+00:00' AIRFLOW_CTX_TRY_NUMBER='1' AIRFLOW_CTX_DAG_RUN_ID='manual__2025-09-16T10:57:25.974337+00:00'
[2025-09-16T10:57:28.182+0000] {logging_mixin.py:188} INFO - Error: column dt.Route_Card_Journal does not exist
LINE 11:             ON pj."Route_Card_Journal" = dt."Route_Card_Jour...
                                                  ^
HINT:  Perhaps you meant to reference the column "dt.Route_Card_Jounal".
[2025-09-16T10:57:28.184+0000] {taskinstance.py:2698} ERROR - Task failed with exception
Traceback (most recent call last):
  File "/home/airflow/.local/lib/python3.8/site-packages/airflow/models/taskinstance.py", line 433, in _execute_task
    result = execute_callable(context=context, **execute_callable_kwargs)
  File "/home/airflow/.local/lib/python3.8/site-packages/airflow/operators/python.py", line 199, in execute
    return_value = self.execute_callable()
  File "/home/airflow/.local/lib/python3.8/site-packages/airflow/operators/python.py", line 216, in execute_callable
    return self.python_callable(*self.op_args, **self.op_kwargs)
  File "/opt/airflow/dags/sql_flow.py", line 38, in create_test_production_summary
    cursor.execute(create_view_query)
psycopg2.errors.UndefinedColumn: column dt.Route_Card_Journal does not exist
LINE 11:             ON pj."Route_Card_Journal" = dt."Route_Card_Jour...
                                                  ^
HINT:  Perhaps you meant to reference the column "dt.Route_Card_Jounal".

[2025-09-16T10:57:28.191+0000] {taskinstance.py:1138} INFO - Marking task as FAILED. dag_id=dag1_test_production_summary, task_id=create_test_production_summary, execution_date=20250916T105725, start_date=20250916T105728, end_date=20250916T105728
[2025-09-16T10:57:28.207+0000] {standard_task_runner.py:107} ERROR - Failed to execute job 3 for task create_test_production_summary (column dt.Route_Card_Journal does not exist
LINE 11:             ON pj."Route_Card_Journal" = dt."Route_Card_Jour...
                                                  ^
HINT:  Perhaps you meant to reference the column "dt.Route_Card_Jounal".
; 79)
[2025-09-16T10:57:28.213+0000] {local_task_job_runner.py:234} INFO - Task exited with return code 1
[2025-09-16T10:57:28.223+0000] {taskinstance.py:3280} INFO - 0 downstream tasks scheduled from follow-on schedule check
