[2025-09-22T08:36:06.408+0000] {taskinstance.py:1956} INFO - Dependencies all met for dep_context=non-requeueable deps ti=<TaskInstance: dag_mockup_test_raw_data_a1.insert_mock_data manual__2025-09-22T08:36:03.973169+00:00 [queued]>
[2025-09-22T08:36:06.413+0000] {taskinstance.py:1956} INFO - Dependencies all met for dep_context=requeueable deps ti=<TaskInstance: dag_mockup_test_raw_data_a1.insert_mock_data manual__2025-09-22T08:36:03.973169+00:00 [queued]>
[2025-09-22T08:36:06.414+0000] {taskinstance.py:2170} INFO - Starting attempt 1 of 1
[2025-09-22T08:36:06.422+0000] {taskinstance.py:2191} INFO - Executing <Task(PythonOperator): insert_mock_data> on 2025-09-22 08:36:03.973169+00:00
[2025-09-22T08:36:06.426+0000] {standard_task_runner.py:60} INFO - Started process 79 to run task
[2025-09-22T08:36:06.428+0000] {standard_task_runner.py:87} INFO - Running: ['***', 'tasks', 'run', 'dag_mockup_test_raw_data_a1', 'insert_mock_data', 'manual__2025-09-22T08:36:03.973169+00:00', '--job-id', '3', '--raw', '--subdir', 'DAGS_FOLDER/moc_data_flow.py', '--cfg-path', '/tmp/tmp9z9esubn']
[2025-09-22T08:36:06.430+0000] {standard_task_runner.py:88} INFO - Job 3: Subtask insert_mock_data
[2025-09-22T08:36:06.466+0000] {task_command.py:423} INFO - Running <TaskInstance: dag_mockup_test_raw_data_a1.insert_mock_data manual__2025-09-22T08:36:03.973169+00:00 [running]> on host 6245f81df034
[2025-09-22T08:36:06.514+0000] {taskinstance.py:2480} INFO - Exporting env vars: AIRFLOW_CTX_DAG_OWNER='***' AIRFLOW_CTX_DAG_ID='dag_mockup_test_raw_data_a1' AIRFLOW_CTX_TASK_ID='insert_mock_data' AIRFLOW_CTX_EXECUTION_DATE='2025-09-22T08:36:03.973169+00:00' AIRFLOW_CTX_TRY_NUMBER='1' AIRFLOW_CTX_DAG_RUN_ID='manual__2025-09-22T08:36:03.973169+00:00'
[2025-09-22T08:36:06.563+0000] {taskinstance.py:2698} ERROR - Task failed with exception
Traceback (most recent call last):
  File "/home/airflow/.local/lib/python3.8/site-packages/airflow/models/taskinstance.py", line 433, in _execute_task
    result = execute_callable(context=context, **execute_callable_kwargs)
  File "/home/airflow/.local/lib/python3.8/site-packages/airflow/operators/python.py", line 199, in execute
    return_value = self.execute_callable()
  File "/home/airflow/.local/lib/python3.8/site-packages/airflow/operators/python.py", line 216, in execute_callable
    return self.python_callable(*self.op_args, **self.op_kwargs)
  File "/opt/airflow/dags/moc_data_flow.py", line 35, in insert_mock_data
    cursor.execute(
psycopg2.errors.StringDataRightTruncation: value too long for type character(1)

[2025-09-22T08:36:06.571+0000] {taskinstance.py:1138} INFO - Marking task as FAILED. dag_id=dag_mockup_test_raw_data_a1, task_id=insert_mock_data, execution_date=20250922T083603, start_date=20250922T083606, end_date=20250922T083606
[2025-09-22T08:36:06.579+0000] {standard_task_runner.py:107} ERROR - Failed to execute job 3 for task insert_mock_data (value too long for type character(1)
; 79)
[2025-09-22T08:36:06.600+0000] {local_task_job_runner.py:234} INFO - Task exited with return code 1
[2025-09-22T08:36:06.610+0000] {taskinstance.py:3280} INFO - 0 downstream tasks scheduled from follow-on schedule check
