[2025-09-24T03:21:24.103+0000] {taskinstance.py:1956} INFO - Dependencies all met for dep_context=non-requeueable deps ti=<TaskInstance: dag_mockup_test_raw_data_2.insert_mock_data_c6 scheduled__2025-09-24T02:00:00+00:00 [queued]>
[2025-09-24T03:21:24.115+0000] {taskinstance.py:1956} INFO - Dependencies all met for dep_context=requeueable deps ti=<TaskInstance: dag_mockup_test_raw_data_2.insert_mock_data_c6 scheduled__2025-09-24T02:00:00+00:00 [queued]>
[2025-09-24T03:21:24.116+0000] {taskinstance.py:2170} INFO - Starting attempt 1 of 1
[2025-09-24T03:21:24.134+0000] {taskinstance.py:2191} INFO - Executing <Task(PythonOperator): insert_mock_data_c6> on 2025-09-24 02:00:00+00:00
[2025-09-24T03:21:24.161+0000] {standard_task_runner.py:60} INFO - Started process 116 to run task
[2025-09-24T03:21:24.180+0000] {standard_task_runner.py:87} INFO - Running: ['***', 'tasks', 'run', 'dag_mockup_test_raw_data_2', 'insert_mock_data_c6', 'scheduled__2025-09-24T02:00:00+00:00', '--job-id', '14', '--raw', '--subdir', 'DAGS_FOLDER/moc_data_flow_2.py', '--cfg-path', '/tmp/tmpqhulckmt']
[2025-09-24T03:21:24.191+0000] {standard_task_runner.py:88} INFO - Job 14: Subtask insert_mock_data_c6
[2025-09-24T03:21:24.399+0000] {task_command.py:423} INFO - Running <TaskInstance: dag_mockup_test_raw_data_2.insert_mock_data_c6 scheduled__2025-09-24T02:00:00+00:00 [running]> on host 0fddc9cfe86c
[2025-09-24T03:21:24.543+0000] {taskinstance.py:2480} INFO - Exporting env vars: AIRFLOW_CTX_DAG_OWNER='***' AIRFLOW_CTX_DAG_ID='dag_mockup_test_raw_data_2' AIRFLOW_CTX_TASK_ID='insert_mock_data_c6' AIRFLOW_CTX_EXECUTION_DATE='2025-09-24T02:00:00+00:00' AIRFLOW_CTX_TRY_NUMBER='1' AIRFLOW_CTX_DAG_RUN_ID='scheduled__2025-09-24T02:00:00+00:00'
[2025-09-24T03:21:24.644+0000] {taskinstance.py:2698} ERROR - Task failed with exception
Traceback (most recent call last):
  File "/home/airflow/.local/lib/python3.8/site-packages/airflow/models/taskinstance.py", line 433, in _execute_task
    result = execute_callable(context=context, **execute_callable_kwargs)
  File "/home/airflow/.local/lib/python3.8/site-packages/airflow/operators/python.py", line 199, in execute
    return_value = self.execute_callable()
  File "/home/airflow/.local/lib/python3.8/site-packages/airflow/operators/python.py", line 216, in execute_callable
    return self.python_callable(*self.op_args, **self.op_kwargs)
  File "/opt/airflow/dags/moc_data_flow_2.py", line 342, in insert_mock_data_c6
    cursor.execute(
psycopg2.errors.NotNullViolation: null value in column "id" of relation "test_raw_data_c6" violates not-null constraint
DETAIL:  Failing row contains (null, 5.06, 1.42, 317, 326, 87, 72, FIX                 , 2025-09-24 03:21:24.627127).

[2025-09-24T03:21:24.715+0000] {taskinstance.py:1138} INFO - Marking task as FAILED. dag_id=dag_mockup_test_raw_data_2, task_id=insert_mock_data_c6, execution_date=20250924T020000, start_date=20250924T032124, end_date=20250924T032124
[2025-09-24T03:21:24.729+0000] {standard_task_runner.py:107} ERROR - Failed to execute job 14 for task insert_mock_data_c6 (null value in column "id" of relation "test_raw_data_c6" violates not-null constraint
DETAIL:  Failing row contains (null, 5.06, 1.42, 317, 326, 87, 72, FIX                 , 2025-09-24 03:21:24.627127).
; 116)
[2025-09-24T03:21:24.771+0000] {local_task_job_runner.py:234} INFO - Task exited with return code 1
[2025-09-24T03:21:24.979+0000] {taskinstance.py:3280} INFO - 0 downstream tasks scheduled from follow-on schedule check
