[2025-09-19T03:25:26.985+0000] {taskinstance.py:1956} INFO - Dependencies all met for dep_context=non-requeueable deps ti=<TaskInstance: dag_production_views_daily.create_summary_availability manual__2025-09-19T03:25:22.598440+00:00 [queued]>
[2025-09-19T03:25:26.990+0000] {taskinstance.py:1956} INFO - Dependencies all met for dep_context=requeueable deps ti=<TaskInstance: dag_production_views_daily.create_summary_availability manual__2025-09-19T03:25:22.598440+00:00 [queued]>
[2025-09-19T03:25:26.991+0000] {taskinstance.py:2170} INFO - Starting attempt 1 of 1
[2025-09-19T03:25:27.000+0000] {taskinstance.py:2191} INFO - Executing <Task(PythonOperator): create_summary_availability> on 2025-09-19 03:25:22.598440+00:00
[2025-09-19T03:25:27.004+0000] {standard_task_runner.py:60} INFO - Started process 91 to run task
[2025-09-19T03:25:27.006+0000] {standard_task_runner.py:87} INFO - Running: ['***', 'tasks', 'run', 'dag_production_views_daily', 'create_summary_availability', 'manual__2025-09-19T03:25:22.598440+00:00', '--job-id', '7', '--raw', '--subdir', 'DAGS_FOLDER/sql_flow.py', '--cfg-path', '/tmp/tmp04wtivya']
[2025-09-19T03:25:27.009+0000] {standard_task_runner.py:88} INFO - Job 7: Subtask create_summary_availability
[2025-09-19T03:25:27.052+0000] {task_command.py:423} INFO - Running <TaskInstance: dag_production_views_daily.create_summary_availability manual__2025-09-19T03:25:22.598440+00:00 [running]> on host 5649ef978325
[2025-09-19T03:25:27.095+0000] {taskinstance.py:2480} INFO - Exporting env vars: AIRFLOW_CTX_DAG_OWNER='***' AIRFLOW_CTX_DAG_ID='dag_production_views_daily' AIRFLOW_CTX_TASK_ID='create_summary_availability' AIRFLOW_CTX_EXECUTION_DATE='2025-09-19T03:25:22.598440+00:00' AIRFLOW_CTX_TRY_NUMBER='1' AIRFLOW_CTX_DAG_RUN_ID='manual__2025-09-19T03:25:22.598440+00:00'
[2025-09-19T03:25:27.153+0000] {logging_mixin.py:188} INFO - ‚ùå Error (create_summary_availability): column d.downtime_hours does not exist
LINE 7:             ROUND((h.hours_for_day - COALESCE(d.downtime_hou...
                                                      ^
[2025-09-19T03:25:27.153+0000] {taskinstance.py:2698} ERROR - Task failed with exception
Traceback (most recent call last):
  File "/home/airflow/.local/lib/python3.8/site-packages/airflow/models/taskinstance.py", line 433, in _execute_task
    result = execute_callable(context=context, **execute_callable_kwargs)
  File "/home/airflow/.local/lib/python3.8/site-packages/airflow/operators/python.py", line 199, in execute
    return_value = self.execute_callable()
  File "/home/airflow/.local/lib/python3.8/site-packages/airflow/operators/python.py", line 216, in execute_callable
    return self.python_callable(*self.op_args, **self.op_kwargs)
  File "/opt/airflow/dags/sql_flow.py", line 272, in create_summary_availability
    cursor.execute(create_view_query)
psycopg2.errors.UndefinedColumn: column d.downtime_hours does not exist
LINE 7:             ROUND((h.hours_for_day - COALESCE(d.downtime_hou...
                                                      ^

[2025-09-19T03:25:27.166+0000] {taskinstance.py:1138} INFO - Marking task as FAILED. dag_id=dag_production_views_daily, task_id=create_summary_availability, execution_date=20250919T032522, start_date=20250919T032526, end_date=20250919T032527
[2025-09-19T03:25:27.180+0000] {standard_task_runner.py:107} ERROR - Failed to execute job 7 for task create_summary_availability (column d.downtime_hours does not exist
LINE 7:             ROUND((h.hours_for_day - COALESCE(d.downtime_hou...
                                                      ^
; 91)
[2025-09-19T03:25:27.219+0000] {local_task_job_runner.py:234} INFO - Task exited with return code 1
[2025-09-19T03:25:27.231+0000] {taskinstance.py:3280} INFO - 0 downstream tasks scheduled from follow-on schedule check
