[2025-09-24T07:11:42.416+0000] {taskinstance.py:1956} INFO - Dependencies all met for dep_context=non-requeueable deps ti=<TaskInstance: dag_mockup_test_raw_data.insert_mock_data_b10 manual__2025-09-24T07:11:33.405271+00:00 [queued]>
[2025-09-24T07:11:42.428+0000] {taskinstance.py:1956} INFO - Dependencies all met for dep_context=requeueable deps ti=<TaskInstance: dag_mockup_test_raw_data.insert_mock_data_b10 manual__2025-09-24T07:11:33.405271+00:00 [queued]>
[2025-09-24T07:11:42.429+0000] {taskinstance.py:2170} INFO - Starting attempt 1 of 1
[2025-09-24T07:11:42.447+0000] {taskinstance.py:2191} INFO - Executing <Task(PythonOperator): insert_mock_data_b10> on 2025-09-24 07:11:33.405271+00:00
[2025-09-24T07:11:42.455+0000] {standard_task_runner.py:60} INFO - Started process 248 to run task
[2025-09-24T07:11:42.461+0000] {standard_task_runner.py:87} INFO - Running: ['***', 'tasks', 'run', 'dag_mockup_test_raw_data', 'insert_mock_data_b10', 'manual__2025-09-24T07:11:33.405271+00:00', '--job-id', '42', '--raw', '--subdir', 'DAGS_FOLDER/moc_data_flow.py', '--cfg-path', '/tmp/tmp37agyhgq']
[2025-09-24T07:11:42.466+0000] {standard_task_runner.py:88} INFO - Job 42: Subtask insert_mock_data_b10
[2025-09-24T07:11:42.536+0000] {task_command.py:423} INFO - Running <TaskInstance: dag_mockup_test_raw_data.insert_mock_data_b10 manual__2025-09-24T07:11:33.405271+00:00 [running]> on host 618c142887f3
[2025-09-24T07:11:42.625+0000] {taskinstance.py:2480} INFO - Exporting env vars: AIRFLOW_CTX_DAG_OWNER='***' AIRFLOW_CTX_DAG_ID='dag_mockup_test_raw_data' AIRFLOW_CTX_TASK_ID='insert_mock_data_b10' AIRFLOW_CTX_EXECUTION_DATE='2025-09-24T07:11:33.405271+00:00' AIRFLOW_CTX_TRY_NUMBER='1' AIRFLOW_CTX_DAG_RUN_ID='manual__2025-09-24T07:11:33.405271+00:00'
[2025-09-24T07:11:42.690+0000] {taskinstance.py:2698} ERROR - Task failed with exception
Traceback (most recent call last):
  File "/home/airflow/.local/lib/python3.8/site-packages/airflow/models/taskinstance.py", line 433, in _execute_task
    result = execute_callable(context=context, **execute_callable_kwargs)
  File "/home/airflow/.local/lib/python3.8/site-packages/airflow/operators/python.py", line 199, in execute
    return_value = self.execute_callable()
  File "/home/airflow/.local/lib/python3.8/site-packages/airflow/operators/python.py", line 216, in execute_callable
    return self.python_callable(*self.op_args, **self.op_kwargs)
  File "/opt/airflow/dags/moc_data_flow.py", line 948, in insert_mock_data
    cursor.execute(
psycopg2.errors.NotNullViolation: null value in column "quantity_ALL" of relation "test_raw_data_b10" violates not-null constraint
DETAIL:  Failing row contains (10, 7.06, 1.35, 94, null, 85, 72, RUN                 , 2025-09-24 07:11:42.67787).

[2025-09-24T07:11:42.714+0000] {taskinstance.py:1138} INFO - Marking task as FAILED. dag_id=dag_mockup_test_raw_data, task_id=insert_mock_data_b10, execution_date=20250924T071133, start_date=20250924T071142, end_date=20250924T071142
[2025-09-24T07:11:42.727+0000] {standard_task_runner.py:107} ERROR - Failed to execute job 42 for task insert_mock_data_b10 (null value in column "quantity_ALL" of relation "test_raw_data_b10" violates not-null constraint
DETAIL:  Failing row contains (10, 7.06, 1.35, 94, null, 85, 72, RUN                 , 2025-09-24 07:11:42.67787).
; 248)
[2025-09-24T07:11:42.760+0000] {local_task_job_runner.py:234} INFO - Task exited with return code 1
[2025-09-24T07:11:42.780+0000] {taskinstance.py:3280} INFO - 0 downstream tasks scheduled from follow-on schedule check
