[2025-09-24T03:21:24.110+0000] {taskinstance.py:1956} INFO - Dependencies all met for dep_context=non-requeueable deps ti=<TaskInstance: dag_mockup_test_raw_data_2.insert_mock_data_c3 scheduled__2025-09-24T02:00:00+00:00 [queued]>
[2025-09-24T03:21:24.123+0000] {taskinstance.py:1956} INFO - Dependencies all met for dep_context=requeueable deps ti=<TaskInstance: dag_mockup_test_raw_data_2.insert_mock_data_c3 scheduled__2025-09-24T02:00:00+00:00 [queued]>
[2025-09-24T03:21:24.124+0000] {taskinstance.py:2170} INFO - Starting attempt 1 of 1
[2025-09-24T03:21:24.140+0000] {taskinstance.py:2191} INFO - Executing <Task(PythonOperator): insert_mock_data_c3> on 2025-09-24 02:00:00+00:00
[2025-09-24T03:21:24.148+0000] {standard_task_runner.py:60} INFO - Started process 114 to run task
[2025-09-24T03:21:24.173+0000] {standard_task_runner.py:87} INFO - Running: ['***', 'tasks', 'run', 'dag_mockup_test_raw_data_2', 'insert_mock_data_c3', 'scheduled__2025-09-24T02:00:00+00:00', '--job-id', '17', '--raw', '--subdir', 'DAGS_FOLDER/moc_data_flow_2.py', '--cfg-path', '/tmp/tmp5svvad2l']
[2025-09-24T03:21:24.193+0000] {standard_task_runner.py:88} INFO - Job 17: Subtask insert_mock_data_c3
[2025-09-24T03:21:24.386+0000] {task_command.py:423} INFO - Running <TaskInstance: dag_mockup_test_raw_data_2.insert_mock_data_c3 scheduled__2025-09-24T02:00:00+00:00 [running]> on host 0fddc9cfe86c
[2025-09-24T03:21:24.550+0000] {taskinstance.py:2480} INFO - Exporting env vars: AIRFLOW_CTX_DAG_OWNER='***' AIRFLOW_CTX_DAG_ID='dag_mockup_test_raw_data_2' AIRFLOW_CTX_TASK_ID='insert_mock_data_c3' AIRFLOW_CTX_EXECUTION_DATE='2025-09-24T02:00:00+00:00' AIRFLOW_CTX_TRY_NUMBER='1' AIRFLOW_CTX_DAG_RUN_ID='scheduled__2025-09-24T02:00:00+00:00'
[2025-09-24T03:21:24.632+0000] {taskinstance.py:2698} ERROR - Task failed with exception
Traceback (most recent call last):
  File "/home/airflow/.local/lib/python3.8/site-packages/airflow/models/taskinstance.py", line 433, in _execute_task
    result = execute_callable(context=context, **execute_callable_kwargs)
  File "/home/airflow/.local/lib/python3.8/site-packages/airflow/operators/python.py", line 199, in execute
    return_value = self.execute_callable()
  File "/home/airflow/.local/lib/python3.8/site-packages/airflow/operators/python.py", line 216, in execute_callable
    return self.python_callable(*self.op_args, **self.op_kwargs)
  File "/opt/airflow/dags/moc_data_flow_2.py", line 164, in insert_mock_data_c3
    cursor.execute(
psycopg2.errors.StringDataRightTruncation: value too long for type character(1)

[2025-09-24T03:21:24.645+0000] {taskinstance.py:1138} INFO - Marking task as FAILED. dag_id=dag_mockup_test_raw_data_2, task_id=insert_mock_data_c3, execution_date=20250924T020000, start_date=20250924T032124, end_date=20250924T032124
[2025-09-24T03:21:24.669+0000] {standard_task_runner.py:107} ERROR - Failed to execute job 17 for task insert_mock_data_c3 (value too long for type character(1)
; 114)
[2025-09-24T03:21:24.725+0000] {local_task_job_runner.py:234} INFO - Task exited with return code 1
[2025-09-24T03:21:24.811+0000] {taskinstance.py:3280} INFO - 0 downstream tasks scheduled from follow-on schedule check
